<?xml version='1.0' encoding='utf-8'?>
<robot xmlns:xacro="http://www.ros.org/wiki/xacro" name="panda">
  <!-- safety_distance: Minimum safety distance in [m] by which the collision volumes are expanded and which is enforced during robot motions -->
  <!-- arm_id: Namespace of the panda arm. Serves to differentiate between arms in case of multiple instances. -->
    
    <link name="panda_link0">
	  <inertial>
        <origin rpy="0 0 0" xyz="0 0 0.05"/>
        <mass value="2.9"/>
        <inertia ixx="0.1" ixy="0" ixz="0" iyy="0.1" iyz="0" izz="0.1"/>
	  </inertial>
      <visual>
        <geometry>
          <mesh filename="package://meshes/visual/link0.dae"/>
        </geometry>
      </visual>
      <collision>
        <origin xyz="-0.075 0 0.06" rpy="0 1.57079632679 0"/>
        <geometry>
          <cylinder radius="0.09" length="0.03" />
        </geometry>
      </collision>
      <collision>
        <origin xyz="-0.06 0 0.06" rpy="0 0 0"/>
        <geometry>
          <sphere radius="0.09" />
        </geometry>
      </collision>
      <collision>
        <origin xyz="-0.09 0 0.06" rpy="0 0 0"/>
        <geometry>
          <sphere radius="0.09" />
        </geometry>
      </collision>
    </link>
    <link name="panda_link1">
	  <inertial>
        <origin rpy="0 0 0" xyz="0 -0.04 -0.05"/>
        <mass value="2.7"/>
        <inertia ixx="0.1" ixy="0" ixz="0" iyy="0.1" iyz="0" izz="0.1"/>
      </inertial>
      <visual>
        <geometry>
          <mesh filename="package://meshes/visual/link1.dae"/>
        </geometry>
      </visual>
      <collision>
        <origin xyz="0 0 -0.1915" rpy="0 0 0"/>
        <geometry>
          <cylinder radius="0.09" length="0.2830" />
        </geometry>
      </collision>
      <collision>
        <origin xyz="0 0 -0.333" rpy="0 0 0"/>
        <geometry>
          <sphere radius="0.09" />
        </geometry>
      </collision>
      <collision>
        <origin xyz="0 0 -0.05" rpy="0 0 0"/>
        <geometry>
          <sphere radius="0.09" />
        </geometry>
      </collision>
    </link>
    <joint name="panda_joint1" type="revolute">
      <safety_controller k_position="100.0" k_velocity="40.0" soft_lower_limit="-2.8973" soft_upper_limit="2.8973"/>
      <origin rpy="0 0 0" xyz="0 0 0.333"/>
      <parent link="panda_link0"/>
      <child link="panda_link1"/>
      <axis xyz="0 0 1"/>
      <limit effort="87" lower="-2.8973" upper="2.8973" velocity="2.1750"/>
    </joint>
    <link name="panda_link2">
	  <inertial>
        <origin rpy="0 0 0" xyz="0 -0.04 0.06"/>
        <mass value="2.73"/>
        <inertia ixx="0.1" ixy="0" ixz="0" iyy="0.1" iyz="0" izz="0.1"/>
      </inertial>
      <visual>
        <geometry>
          <mesh filename="package://meshes/visual/link2.dae"/>
        </geometry>
      </visual>
      <collision>
        <origin xyz="0 0 0" rpy="0 0 0"/>
        <geometry>
          <cylinder radius="0.09" length="0.12" />
        </geometry>
      </collision>
      <collision>
        <origin xyz="0 0 -0.06" rpy="0 0 0"/>
        <geometry>
          <sphere radius="0.09" />
        </geometry>
      </collision>
      <collision>
        <origin xyz="0 0 0.06" rpy="0 0 0"/>
        <geometry>
          <sphere radius="0.09" />
        </geometry>
      </collision>
    </link>
    <joint name="panda_joint2" type="revolute">
      <safety_controller k_position="100.0" k_velocity="40.0" soft_lower_limit="-1.7628" soft_upper_limit="1.7628"/>
      <origin rpy="-1.57079632679 0 0" xyz="0 0 0"/>
      <parent link="panda_link1"/>
      <child link="panda_link2"/>
      <axis xyz="0 0 1"/>
      <limit effort="87" lower="-1.7628" upper="1.7628" velocity="2.1750"/>
    </joint>
    
    
    <link name="panda_link3">
	  <inertial>
        <origin rpy="0 0 0" xyz="0.01 0.01 -0.05"/>
        <mass value="2.04"/>
        <inertia ixx="0.1" ixy="0" ixz="0" iyy="0.1" iyz="0" izz="0.1"/>
      </inertial>
      <visual>
        <geometry>
          <mesh filename="package://meshes/visual/link3.dae"/>
        </geometry>
      </visual>
      <collision>
        <origin xyz="0 0 -0.145" rpy="0 0 0"/>
        <geometry>
          <cylinder radius="0.09" length="0.15" />
        </geometry>
      </collision>
      <collision>
        <origin xyz="0 0 -0.22" rpy="0 0 0"/>
        <geometry>
          <sphere radius="0.09" />
        </geometry>
      </collision>
      <collision>
        <origin xyz="0 0 -0.07" rpy="0 0 0"/>
        <geometry>
          <sphere radius="0.09" />
        </geometry>
      </collision>
    </link>
    <joint name="panda_joint3" type="revolute">
      <safety_controller k_position="100.0" k_velocity="40.0" soft_lower_limit="-2.8973" soft_upper_limit="2.8973"/>
      <origin rpy="1.57079632679 0 0" xyz="0 -0.316 0"/>
      <parent link="panda_link2"/>
      <child link="panda_link3"/>
      <axis xyz="0 0 1"/>
      <limit effort="87" lower="-2.8973" upper="2.8973" velocity="2.1750"/>
    </joint>
    <link name="panda_link4">
	  <inertial>
        <origin rpy="0 0 0" xyz="-0.03 0.03 0.02"/>
        <mass value="2.08"/>
        <inertia ixx="0.1" ixy="0" ixz="0" iyy="0.1" iyz="0" izz="0.1"/>
      </inertial>
      <visual>
        <geometry>
          <mesh filename="package://meshes/visual/link4.dae"/>
        </geometry>
      </visual>
      <collision>
        <origin xyz="0 0 0" rpy="0 0 0"/>
        <geometry>
          <cylinder radius="0.09" length="0.12" />
        </geometry>
      </collision>
      <collision>
        <origin xyz="0 0 0.06" rpy="0 0 0"/>
        <geometry>
          <sphere radius="0.09" />
        </geometry>
      </collision>
      <collision>
        <origin xyz="0 0 -0.06" rpy="0 0 0"/>
        <geometry>
          <sphere radius="0.09" />
        </geometry>
      </collision>
    </link>
    <joint name="panda_joint4" type="revolute">
      <safety_controller k_position="100.0" k_velocity="40.0" soft_lower_limit="-3.0718" soft_upper_limit="-0.0698"/>
      <origin rpy="1.57079632679 0 0" xyz="0.0825 0 0"/>
      <parent link="panda_link3"/>
      <child link="panda_link4"/>
      <axis xyz="0 0 1"/>
      <limit effort="87" lower="-3.0718" upper="-0.0698" velocity="2.1750"/>
    </joint>
    <link name="panda_link5">
	  <inertial>
        <origin rpy="0 0 0" xyz="0 0.04 -0.12"/>
        <mass value="3"/>
        <inertia ixx="0.1" ixy="0" ixz="0" iyy="0.1" iyz="0" izz="0.1"/>
      </inertial>
      <visual>
        <geometry>
          <mesh filename="package://meshes/visual/link5.dae"/>
        </geometry>
      </visual>
      <collision>
        <origin xyz="0 0 -0.26" rpy="0 0 0"/>
        <geometry>
          <cylinder radius="0.09" length="0.1" />
        </geometry>
      </collision>
      <collision>
        <origin xyz="0 0 -0.31" rpy="0 0 0"/>
        <geometry>
          <sphere radius="0.09" />
        </geometry>
      </collision>
      <collision>
        <origin xyz="0 0 -0.21" rpy="0 0 0"/>
        <geometry>
          <sphere radius="0.09" />
        </geometry>
      </collision>
      <collision>
        <origin xyz="0 0.08 -0.13" rpy="0 0 0"/>
        <geometry>
          <cylinder radius="0.055" length="0.14" />
        </geometry>
      </collision>
      <collision>
        <origin xyz="0 0.08 -0.06" rpy="0 0 0"/>
        <geometry>
          <sphere radius="0.055" />
        </geometry>
      </collision>
      <collision>
        <origin xyz="0 0.08 -0.20" rpy="0 0 0"/>
        <geometry>
          <sphere radius="0.055" />
        </geometry>
      </collision>

    </link>
    <joint name="panda_joint5" type="revolute">
      <safety_controller k_position="100.0" k_velocity="40.0" soft_lower_limit="-2.8973" soft_upper_limit="2.8973"/>
      <origin rpy="-1.57079632679 0 0" xyz="-0.0825 0.384 0"/>
      <parent link="panda_link4"/>
      <child link="panda_link5"/>
      <axis xyz="0 0 1"/>
      <limit effort="12" lower="-2.8973" upper="2.8973" velocity="2.6100"/>
    </joint>
    <link name="panda_link6">
	  <inertial>
        <origin rpy="0 0 0" xyz="0.04 0 0"/>
        <mass value="1.3"/>
        <inertia ixx="0.1" ixy="0" ixz="0" iyy="0.1" iyz="0" izz="0.1"/>
      </inertial>
      <visual>
        <geometry>
          <mesh filename="package://meshes/visual/link6.dae"/>
        </geometry>
      </visual>
      <collision>
        <origin xyz="0 0 -0.03" rpy="0 0 0"/>
        <geometry>
          <cylinder radius="0.08" length="0.08" />
        </geometry>
      </collision>
      <collision>
        <origin xyz="0 0 0.01" rpy="0 0 0"/>
        <geometry>
          <sphere radius="0.08" />
        </geometry>
      </collision>
      <collision>
        <origin xyz="0 0 -0.07" rpy="0 0 0"/>
        <geometry>
          <sphere radius="0.08" />
        </geometry>
      </collision>
    </link>
    <joint name="panda_joint6" type="revolute">
      <safety_controller k_position="100.0" k_velocity="40.0" soft_lower_limit="-0.0175" soft_upper_limit="3.7525"/>
      <origin rpy="1.57079632679 0 0" xyz="0 0 0"/>
      <parent link="panda_link5"/>
      <child link="panda_link6"/>
      <axis xyz="0 0 1"/>
      <limit effort="12" lower="-0.0175" upper="3.7525" velocity="2.6100"/>
    </joint>
    <link name="panda_link7">
	  <inertial>
        <origin rpy="0 0 0" xyz="0 0 0.08"/>
        <mass value=".2"/>
        <inertia ixx="0.1" ixy="0" ixz="0" iyy="0.1" iyz="0" izz="0.1"/>
      </inertial>
      <visual>
        <geometry>
          <mesh filename="package://meshes/visual/link7.dae"/>
        </geometry>
      </visual>
      <collision>
        <origin xyz="0 0 0.01" rpy="0 0 0"/>
        <geometry>
          <cylinder radius="0.07" length="0.14" />
        </geometry>
      </collision>
      <collision>
        <origin xyz="0 0 0.08" rpy="0 0 0"/>
        <geometry>
          <sphere radius="0.07"  />
        </geometry>
      </collision>
      <collision>
        <origin xyz="0 0 -0.06" rpy="0 0 0"/>
        <geometry>
          <sphere radius="0.07"  />
        </geometry>
      </collision>
    </link>
    <joint name="panda_joint7" type="revolute">
      <safety_controller k_position="100.0" k_velocity="40.0" soft_lower_limit="-2.8973" soft_upper_limit="2.8973"/>
      <origin rpy="1.57079632679 0 0" xyz="0.088 0 0"/>
      <parent link="panda_link6"/>
      <child link="panda_link7"/>
      <axis xyz="0 0 1"/>
      <limit effort="12" lower="-2.8973" upper="2.8973" velocity="2.6100"/>
    </joint>
    
    <link name="panda_link8">
	  <inertial>
        <origin rpy="0 0 0" xyz="0 0 0"/>
        <mass value="0.0"/>
        <inertia ixx="0.1" ixy="0" ixz="0" iyy="0.1" iyz="0" izz="0.1"/>
      </inertial>
      <!--
      <collision>
        <origin xyz="0.0424 0.0424 -0.0250" rpy="3.14159265359 1.57079632679 1.57079632679"/>
        <geometry>
          <cylinder radius="0.06"  length="0.01" />
        </geometry>
      </collision>-->
      <!--<collision>
        <origin xyz="0.0424 0.0424 -0.02" rpy="0 0 0"/>
        <geometry>
          <sphere radius="0.06"  />
        </geometry>
      </collision>
      <collision>
        <origin xyz="0.0424 0.0424 -0.03" rpy="0 0 0"/>
        <geometry>
          <sphere radius="0.06"  />
        </geometry>
      </collision>
      -->
    </link>
    
    
    <joint name="panda_joint8" type="fixed">
      <origin rpy="0 0 0" xyz="0 0 0.107"/>
      <parent link="panda_link7"/>
      <child link="panda_link8"/>
    </joint>
    
    
      <joint name="panda_hand_joint" type="fixed">
        <parent link="panda_link8"/>
        <child link="panda_hand"/>
        <origin xyz="0 0 0" rpy="0 0 -0.785398163397"/>
      </joint>
    
    <link name="panda_hand">
	  <inertial>
        <origin rpy="0 0 0" xyz="0 0 0.04"/>
        <mass value=".81"/>
        <inertia ixx="0.1" ixy="0" ixz="0" iyy="0.1" iyz="0" izz="0.1"/>
      </inertial>
      <visual>
        <geometry>
          <mesh filename="package://meshes/visual/hand.dae"/>
        </geometry>
      </visual>
      <!--<collision>
        <origin xyz="0 0 0.04" rpy="0 1.57079632679 1.57079632679"/>
        <geometry>
          <cylinder radius="0.07" length="0.1" />
        </geometry>
      </collision>
      <collision>
        <origin xyz="0 -0.05 0.04" rpy="0 0 0"/>
        <geometry>
          <sphere radius="0.07"  />
        </geometry>
      </collision>
      <collision>
        <origin xyz="0 0.05 0.04" rpy="0 0 0"/>
        <geometry>
          <sphere radius="0.07"  />
        </geometry>
      </collision>
      <collision>
        <origin xyz="0 0 0.1" rpy="0 1.57079632679 1.57079632679"/>
        <geometry>
          <cylinder radius="0.05" length="0.1" />
        </geometry>
      </collision>
      <collision>
        <origin xyz="0 -0.05 0.1" rpy="0 0 0"/>
        <geometry>
          <sphere radius="0.05"  />
        </geometry>
      </collision>
      <collision>
        <origin xyz="0 0.05 0.1" rpy="0 0 0"/>
        <geometry>
          <sphere radius="0.05"  />
        </geometry>
      </collision>-->
    </link>
    
    
    <link name="panda_hand_tcp">
      <inertial>
        <mass value="0"/>
        <inertia ixx="0.0" ixy="0.0" ixz="0.0" iyy="0.0" iyz="0.0" izz="0.0"/>
      </inertial>
    </link> 
    
    <joint name="panda_hand_tcp_joint" type="fixed">
      <origin xyz="0 0 0.1034" rpy="0 0 0" />
      <parent link="panda_hand" />
      <child link="panda_hand_tcp" />
    </joint>
    <link name="panda_leftfinger">
	  <inertial>
        <origin rpy="0 0 0" xyz="0 0.01 0.02"/>
        <mass value="0.1"/>
        <inertia ixx="0.1" ixy="0" ixz="0" iyy="0.1" iyz="0" izz="0.1"/>
      </inertial>
      <visual>
        <geometry>
          <mesh filename="package://meshes/visual/finger.dae"/>
        </geometry>
      </visual>
    </link>
    <link name="panda_rightfinger">
	  <inertial>
        <origin rpy="0 0 0" xyz="0 -0.01 0.02"/>
        <mass value="0.1"/>
        <inertia ixx="0.1" ixy="0" ixz="0" iyy="0.1" iyz="0" izz="0.1"/>
      </inertial>
      <visual>
        <origin xyz="0 0 0" rpy="0 0 3.14159265359"/>
        <geometry>
          <mesh filename="package://meshes/visual/finger.dae"/>
        </geometry>
      </visual>
   </link>
    <joint name="panda_finger_joint1" type="prismatic">
      <parent link="panda_hand"/>
      <child link="panda_leftfinger"/>
      <origin xyz="0 0 0.0584" rpy="0 0 0"/>
      <axis xyz="0 1 0"/>
      <limit effort="100" lower="0.0" upper="0.04" velocity="0.2"/>
    </joint>
    <joint name="panda_finger_joint2" type="prismatic">
      <parent link="panda_hand"/>
      <child link="panda_rightfinger"/>
      <origin xyz="0 0 0.0584" rpy="0 0 0"/>
      <axis xyz="0 -1 0"/>
      <limit effort="100" lower="0.0" upper="0.04" velocity="0.2"/>
      <mimic joint="panda_finger_joint1" />
    </joint>
    
</robot>
